Workbook

Sheet Author metrics
A1: Id do autor | B1: Nome do autor | C1: afiliação | D1: Produção Científica (2015-2024) | E1: Número de citações | F1: Citações por publicação | G1: Indice H | H1: Impacto das citações ponderado por discipina | I1: Publicações nas revistas Top 1% | J1: Publicações nas revistas Top 5% | K1: Publicações nas revistas Top 10% | L1: Publicações nas revistas Top 25% | M1: Publicações nas revistas Top 50% | N1: Publicações nas revistas Top 75% | P1: Artigos entre os 1% mais citados | Q1: Artigos entre os 5% mais citados | R1: Artigos entre os 10% mais citados | S1: Artigos entre os 25% mais citados
A2: author_id | B2: author_name | C2: afiliation | D2: Scholarly Output (2015-2024) | E2: Citation Count | F2: Citations Per Publication | G2: H Index | H2: Field Weighted Citation Impact | I2: Top Journal Percentiles_1% Value | J2: Top Journal Percentiles_5% Value | K2: Top Journal Percentiles_10% Value | L2: Top Journal Percentiles_25% Value | M2: Top Journal Percentiles_50% Value | N2: Top Journal Percentiles_75% Value | P2: Top Citation Percentiles_1% Value | Q2: Top Citation Percentiles_5% Value | R2: Top Citation Percentiles_10% Value | S2: Top Citation Percentiles_25%_Value
A3: 7203013507 | B3: Martíns, André Leibsohn | C3: =_xlfn.XLOOKUP(A3,Afiliation!$B$2:$B$4079,Afiliation!$D$2:$D$4079,0) -> Petrobras | D3: 67 | E3: 513 | F3: 7.6567163 | G3: 21 | H3: 1.13 | I3: 0 | J3: 0 | K3: 1 | L3: 16 | M3: 17 | N3: 27 | P3: 0 | Q3: 0 | R3: 2 | S3: 8
A4: 57193800495 | B4: Oliveira, Elcio Cruz De | C4: =_xlfn.XLOOKUP(A4,Afiliation!$B$2:$B$4079,Afiliation!$D$2:$D$4079,0) -> Pontifícia Universidade Católica do Rio de Janeiro | D4: 73 | E4: 425 | F4: 5.821918 | G4: 15 | H4: 0.35 | I4: 0 | J4: 7 | K4: 16 | L4: 29 | M4: 42 | N4: 59 | P4: 0 | Q4: 0 | R4: 1 | S4: 8
A5: 25636732500 | B5: Emerick, Alexandre A. | C5: =_xlfn.XLOOKUP(A5,Afiliation!$B$2:$B$4079,Afiliation!$D$2:$D$4079,0) -> Petrobras | D5: 47 | E5: 1029 | F5: 21.893618 | G5: 24 | H5: 2.59 | I5: 0 | J5: 0 | K5: 5 | L5: 21 | M5: 23 | N5: 27 | P5: 0 | Q5: 4 | R5: 7 | S5: 16
A6: 7101666440 | B6: Castro, Aline M. | C6: =_xlfn.XLOOKUP(A6,Afiliation!$B$2:$B$4079,Afiliation!$D$2:$D$4079,0) -> Petrobras | D6: 81 | E6: 2624 | F6: 32.39506 | G6: 36 | H6: 1.11 | I6: 1 | J6: 9 | K6: 17 | L6: 43 | M6: 71 | N6: 75 | P6: 1 | Q6: 9 | R6: 19 | S6: 51
A7: 56890937900 | B7: Schnitzler, Eduardo | C7: =_xlfn.XLOOKUP(A7,Afiliation!$B$2:$B$4079,Afiliation!$D$2:$D$4079,0) -> Petrobras | D7: 26 | E7: 120 | F7: 4.6153846 | G7: 7 | H7: 1.47 | I7: 0 | J7: 0 | K7: 0 | L7: 0 | M7: 2 | N7: 10 | P7: 0 | Q7: 0 | R7: 0 | S7: 0
A8: 36652958600 | B8: Barbosa Machado, Marcos Vitor | C8: =_xlfn.XLOOKUP(A8,Afiliation!$B$2:$B$4079,Afiliation!$D$2:$D$4079,0) -> Petrobras | D8: 23 | E8: 176 | F8: 7.652174 | G8: 8 | H8: 2.48 | I8: 0 | J8: 2 | K8: 5 | L8: 10 | M8: 12 | N8: 14 | P8: 0 | Q8: 2 | R8: 4 | S8: 11
A9: 57201090782 | B9: Schwalbert, Mateus Palharini | C9: =_xlfn.XLOOKUP(A9,Afiliation!$B$2:$B$4079,Afiliation!$D$2:$D$4079,0) -> Petrobras | D9: 32 | E9: 414 | F9: 12.9375 | G9: 12 | H9: 2.97 | I9: 0 | J9: 2 | K9: 7 | L9: 10 | M9: 17 | N9: 23 | P9: 0 | Q9: 0 | R9: 1 | S9: 14
A10: 57191364677 | B10: Tedeschi, Leonardo R. | C10: =_xlfn.XLOOKUP(A10,Afiliation!$B$2:$B$4079,Afiliation!$D$2:$D$4079,0) -> Petrobras | D10: 11 | E10: 717 | F10: 65.181816 | G10: 10 | H10: 3.38 | I10: 0 | J10: 6 | K10: 10 | L10: 10 | M10: 11 | N10: 11 | P10: 1 | Q10: 5 | R10: 7 | S10: 7
A11: 57189617898 | B11: Maul, Alexandre Rodrigo M. | C11: =_xlfn.XLOOKUP(A11,Afiliation!$B$2:$B$4079,Afiliation!$D$2:$D$4079,0) -> Petrobras | D11: 31 | E11: 209 | F11: 6.7419353 | G11: 8 | H11: 1.79 | I11: 1 | J11: 2 | K11: 2 | L11: 5 | M11: 8 | N11: 9 | P11: 0 | Q11: 0 | R11: 0 | S11: 1
A12: 57191664290 | B12: de Souza, Jorge André Braz | C12: =_xlfn.XLOOKUP(A12,Afiliation!$B$2:$B$4079,Afiliation!$D$2:$D$4079,0) -> Petrobras | D12: 23 | E12: 405 | F12: 17.608696 | G12: 14 | H12: 1.75 | I12: 0 | J12: 7 | K12: 8 | L12: 19 | M12: 19 | N12: 20 | P12: 0 | Q12: 0 | R12: 3 | S12: 15
A13: 23090256500 | B13: Campello, George Carneiro | C13: =_xlfn.XLOOKUP(A13,Afiliation!$B$2:$B$4079,Afiliation!$D$2:$D$4079,0) -> Petrobras | D13: 16 | E13: 75 | F13: 4.6875 | G13: 8 | H13: 1.04 | I13: 0 | J13: 0 | K13: 0 | L13: 1 | M13: 3 | N13: 11 | P13: 0 | Q13: 0 | R13: 0 | S13: 1
A14: 16200428400 | B14: Pinho, Andrea De Rezende | C14: =_xlfn.XLOOKUP(A14,Afiliation!$B$2:$B$4079,Afiliation!$D$2:$D$4079,0) -> Petrobras | D14: 11 | E14: 646 | F14: 58.727272 | G14: 12 | H14: 2.07 | I14: 0 | J14: 3 | K14: 8 | L14: 10 | M14: 10 | N14: 11 | P14: 0 | Q14: 3 | R14: 5 | S14: 8
... A41: 36155938800 | B41: Pinto, Antônio Carlos Capeleiro | C41: =_xlfn.XLOOKUP(A41,Afiliation!$B$2:$B$4079,Afiliation!$D$2:$D$4079,0) -> Petrobras | D41: 5 | E41: 118 | F41: 23.6 | G41: 9 | H41: 3.44 | I41: 0 | J41: 0 | K41: 0 | L41: 0 | M41: 0 | N41: 3 | P41: 0 | Q41: 0 | R41: 0 | S41: 2
A42: 55398602300 | B42: Furtado, Claudio A. | C42: =_xlfn.XLOOKUP(A42,Afiliation!$B$2:$B$4079,Afiliation!$D$2:$D$4079,0) -> Petrobras | D42: 1 | E42: 1 | F42: 1 | G42: 12 | H42: 1.58 | P42: 0 | Q42: 0 | R42: 0 | S42: 0
A43: 56094347300 | B43: Cazarin, Caroline Lessio | C43: =_xlfn.XLOOKUP(A43,Afiliation!$B$2:$B$4079,Afiliation!$D$2:$D$4079,0) -> Petrobras | D43: 54 | E43: 839 | F43: 15.537037 | G43: 17 | H43: 0.89 | I43: 2 | J43: 6 | K43: 18 | L43: 25 | M43: 30 | N43: 42 | P43: 0 | Q43: 1 | R43: 7 | S43: 18
A44: 59830428600 | B44: Paes, Marcelo Torres Piza | C44: =_xlfn.XLOOKUP(A44,Afiliation!$B$2:$B$4079,Afiliation!$D$2:$D$4079,0) -> Petrobras | D44: 30 | E44: 233 | F44: 7.766667 | G44: 12 | H44: 0.42 | I44: 0 | J44: 0 | K44: 1 | L44: 8 | M44: 21 | N44: 26 | P44: 0 | Q44: 0 | R44: 1 | S44: 5
A45: 35810173300 | B45: de Oliveira, Márcia Cristina Khalil | C45: =_xlfn.XLOOKUP(A45,Afiliation!$B$2:$B$4079,Afiliation!$D$2:$D$4079,0) -> Petrobras | D45: 27 | E45: 282 | F45: 10.444445 | G45: 13 | H45: 0.68 | I45: 0 | J45: 2 | K45: 5 | L45: 15 | M45: 16 | N45: 19 | P45: 0 | Q45: 0 | R45: 0 | S45: 5
A46: 7202385399 | B46: Teixeira, A. | C46: =_xlfn.XLOOKUP(A46,Afiliation!$B$2:$B$4079,Afiliation!$D$2:$D$4079,0) -> Petrobras | D46: 23 | E46: 246 | F46: 10.695652 | G46: 10 | H46: 0.88 | I46: 0 | J46: 2 | K46: 4 | L46: 14 | M46: 15 | N46: 19 | P46: 0 | Q46: 0 | R46: 0 | S46: 7
A47: 7103359019 | B47: Ferreira, Francisco Henriques | C47: =_xlfn.XLOOKUP(A47,Afiliation!$B$2:$B$4079,Afiliation!$D$2:$D$4079,0) -> Petrobras | D47: 15 | E47: 25 | F47: 1.6666666 | G47: 6 | H47: 0.72 | I47: 0 | J47: 0 | K47: 0 | L47: 1 | M47: 2 | N47: 2 | P47: 0 | Q47: 0 | R47: 0 | S47: 0
A48: 7103355279 | B48: Figueiredo, Milene Freitas | C48: =_xlfn.XLOOKUP(A48,Afiliation!$B$2:$B$4079,Afiliation!$D$2:$D$4079,0) -> Petrobras | D48: 12 | E48: 382 | F48: 31.833334 | G48: 11 | H48: 2.02 | I48: 1 | J48: 6 | K48: 9 | L48: 10 | M48: 11 | N48: 12 | P48: 0 | Q48: 3 | R48: 4 | S48: 8
A49: 26656553600 | B49: De Almeida, Marlon Brando Bezerra | C49: =_xlfn.XLOOKUP(A49,Afiliation!$B$2:$B$4079,Afiliation!$D$2:$D$4079,0) -> Petrobras | D49: 12 | E49: 567 | F49: 47.25 | G49: 12 | H49: 1.63 | I49: 0 | J49: 2 | K49: 7 | L49: 9 | M49: 10 | N49: 12 | P49: 0 | Q49: 2 | R49: 5 | S49: 7
A50: 7006427170 | B50: Chaves, Érica Gervasoni | C50: =_xlfn.XLOOKUP(A50,Afiliation!$B$2:$B$4079,Afiliation!$D$2:$D$4079,0) -> Universidade Federal do Rio de Janeiro | D50: 16 | E50: 144 | F50: 9 | G50: 8 | H50: 0.52 | I50: 0 | J50: 1 | K50: 2 | L50: 7 | M50: 12 | N50: 16 | P50: 0 | Q50: 0 | R50: 0 | S50: 6
A51: 36971232400 | B51: Marques, Marcello A.Rodrigues | C51: =_xlfn.XLOOKUP(A51,Afiliation!$B$2:$B$4079,Afiliation!$D$2:$D$4079,0) -> Petrobras | D51: 10 | E51: 61 | F51: 6.1 | G51: 4 | H51: 2.11 | I51: 0 | J51: 0 | K51: 0 | L51: 0 | M51: 0 | N51: 7 | P51: 0 | Q51: 0 | R51: 0 | S51: 0
A52: 6506708809 | B52: Jacinto, Carlos Magno Couto | C52: =_xlfn.XLOOKUP(A52,Afiliation!$B$2:$B$4079,Afiliation!$D$2:$D$4079,0) -> Petrobras | D52: 11 | E52: 108 | F52: 9.818182 | G52: 9 | H52: 0.78 | I52: 0 | J52: 1 | K52: 1 | L52: 3 | M52: 6 | N52: 6 | P52: 0 | Q52: 0 | R52: 0 | S52: 2
A53: 35618276400 | B53: Menezes, Paulo de Tarso Luiz | C53: =_xlfn.XLOOKUP(A53,Afiliation!$B$2:$B$4079,Afiliation!$D$2:$D$4079,0) -> Unknown affiliation | D53: 33 | E53: 120 | F53: 3.6363637 | G53: 12 | H53: 0.57 | I53: 0 | J53: 0 | K53: 1 | L53: 4 | M53: 19 | N53: 22 | P53: 0 | Q53: 0 | R53: 0 | S53: 1
A54: 7005906505 | B54: Morgado, Edisson | C54: =_xlfn.XLOOKUP(A54,Afiliation!$B$2:$B$4079,Afiliation!$D$2:$D$4079,0) -> Petrobras | D54: 10 | E54: 147 | F54: 14.7 | G54: 16 | H54: 0.51 | I54: 0 | J54: 0 | K54: 3 | L54: 8 | M54: 10 | N54: 10 | P54: 0 | Q54: 1 | R54: 1 | S54: 3
... A64: 6506462205 | B64: Moure, Gustavo Torres | C64: =_xlfn.XLOOKUP(A64,Afiliation!$B$2:$B$4079,Afiliation!$D$2:$D$4079,0) -> Petrobras | D64: 6 | E64: 76 | F64: 12.666667 | G64: 10 | H64: 0.58 | I64: 0 | J64: 1 | K64: 3 | L64: 3 | M64: 3 | N64: 3 | P64: 0 | Q64: 0 | R64: 0 | S64: 2
A65: 7004501367 | B65: de Sá, Carlos Henrique Marques | C65: =_xlfn.XLOOKUP(A65,Afiliation!$B$2:$B$4079,Afiliation!$D$2:$D$4079,0) -> Petrobras | D65: 4 | E65: 38 | F65: 9.5 | G65: 7 | H65: 3.2 | P65: 0 | Q65: 0 | R65: 0 | S65: 1
A66: 57197084486 | B66: Fonseca, Teresa Cristina O. | C66: =_xlfn.XLOOKUP(A66,Afiliation!$B$2:$B$4079,Afiliation!$D$2:$D$4079,0) -> Petrobras | D66: 4 | E66: 29 | F66: 7.25 | G66: 12 | H66: 0.78 | I66: 0 | J66: 0 | K66: 1 | L66: 1 | M66: 2 | N66: 2 | P66: 0 | Q66: 0 | R66: 0 | S66: 0
A67: 7102099114 | B67: de Carvalho, Carlos Henrique Monteiro | C67: =_xlfn.XLOOKUP(A67,Afiliation!$B$2:$B$4079,Afiliation!$D$2:$D$4079,0) -> Petrobras | D67: 3 | E67: 99 | F67: 33 | G67: 8 | H67: 1.34 | I67: 0 | J67: 1 | K67: 2 | L67: 3 | M67: 3 | N67: 3 | P67: 0 | Q67: 0 | R67: 1 | S67: 2
A68: 55194930100 | B68: Bezerra, Maria Carmen Moreira | C68: =_xlfn.XLOOKUP(A68,Afiliation!$B$2:$B$4079,Afiliation!$D$2:$D$4079,0) -> Petrobras | D68: 2 | E68: 13 | F68: 6.5 | G68: 13 | H68: 0.55 | I68: 0 | J68: 1 | K68: 1 | L68: 1 | M68: 1 | N68: 1 | P68: 0 | Q68: 0 | R68: 0 | S68: 0
A69: 35995240900 | B69: Fernandes, Paulo Dore | C69: =_xlfn.XLOOKUP(A69,Afiliation!$B$2:$B$4079,Afiliation!$D$2:$D$4079,0) -> Petrobras | D69: 1 | E69: 53 | F69: 53 | G69: 8 | H69: 2.29 | I69: 0 | J69: 0 | K69: 0 | L69: 1 | M69: 1 | N69: 1 | P69: 0 | Q69: 0 | R69: 1 | S69: 1
A70: 7102859116 | B70: Carvalho, Paulo Marcus | C70: =_xlfn.XLOOKUP(A70,Afiliation!$B$2:$B$4079,Afiliation!$D$2:$D$4079,0) -> Petrobras | D70: 2 | E70: 137 | F70: 68.5 | G70: 8 | H70: 24.68 | P70: 0 | Q70: 1 | R70: 1 | S70: 2
A71: 55978767400 | B71: Carnier Fragoso, Daniel Galvão | C71: =_xlfn.XLOOKUP(A71,Afiliation!$B$2:$B$4079,Afiliation!$D$2:$D$4079,0) -> Unknown affiliation | D71: 13 | E71: 186 | F71: 14.307693 | G71: 7 | H71: 0.69 | I71: 1 | J71: 5 | K71: 6 | L71: 9 | M71: 12 | N71: 12 | P71: 0 | Q71: 0 | R71: 1 | S71: 4
A72: 14040136600 | B72: de Abreu, Marco A.S. | C72: =_xlfn.XLOOKUP(A72,Afiliation!$B$2:$B$4079,Afiliation!$D$2:$D$4079,0) -> Petrobras | D72: 1 | E72: 16 | F72: 16 | G72: 10 | H72: 0.25 | I72: 0 | J72: 0 | K72: 0 | L72: 1 | M72: 1 | N72: 1 | P72: 0 | Q72: 0 | R72: 0 | S72: 0
A73: 55611817600 | B73: Spigolon, André Luiz Durante | C73: =_xlfn.XLOOKUP(A73,Afiliation!$B$2:$B$4079,Afiliation!$D$2:$D$4079,0) -> Petrobras | D73: 30 | E73: 381 | F73: 12.7 | G73: 10 | H73: 0.88 | I73: 0 | J73: 3 | K73: 8 | L73: 14 | M73: 18 | N73: 27 | P73: 0 | Q73: 2 | R73: 4 | S73: 5
A74: 57201120138 | B74: de Oliveira Carmo, Isabela O. | C74: =_xlfn.XLOOKUP(A74,Afiliation!$B$2:$B$4079,Afiliation!$D$2:$D$4079,0) -> Petrobras | D74: 21 | E74: 298 | F74: 14.190476 | G74: 10 | H74: 0.81 | I74: 1 | J74: 3 | K74: 7 | L74: 13 | M74: 15 | N74: 16 | P74: 0 | Q74: 0 | R74: 2 | S74: 7
A75: 57203410813 | B75: Santos, Hugo Francisco Lisboa | C75: =_xlfn.XLOOKUP(A75,Afiliation!$B$2:$B$4079,Afiliation!$D$2:$D$4079,0) -> Petrobras | D75: 24 | E75: 88 | F75: 3.6666667 | G75: 6 | H75: 1.22 | I75: 0 | J75: 0 | K75: 0 | L75: 4 | M75: 7 | N75: 12 | P75: 0 | Q75: 0 | R75: 0 | S75: 1
...

Sheet Afiliation
A1: Name | B1: Scopus author ID | C1: Scopus author profile | D1: Primary author affiliation* | E1: ORCID (linked to Scopus author profile)
A2: Martíns, André Leibsohn | B2: 7203013507 | C2: https://www.scopus.com/authid/detail.url?authorId=7203013507 | D2: Petrobras
A3: Oliveira, Elcio Cruz De | B3: 57193800495 | C3: https://www.scopus.com/authid/detail.url?authorId=57193800495 | D3: Pontifícia Universidade Católica do Rio de Janeiro | E3: 0000-0001-8979-4131
A4: Emerick, Alexandre A. | B4: 25636732500 | C4: https://www.scopus.com/authid/detail.url?authorId=25636732500 | D4: Petrobras | E4: 0000-0002-4921-4902
A5: Castro, Aline M. | B5: 7101666440 | C5: https://www.scopus.com/authid/detail.url?authorId=7101666440 | D5: Petrobras | E5: 0000-0002-1355-8455
A6: Schnitzler, Eduardo | B6: 56890937900 | C6: https://www.scopus.com/authid/detail.url?authorId=56890937900 | D6: Petrobras
A7: Barbosa Machado, Marcos Vitor | B7: 36652958600 | C7: https://www.scopus.com/authid/detail.url?authorId=36652958600 | D7: Petrobras
A8: Schwalbert, Mateus Palharini | B8: 57201090782 | C8: https://www.scopus.com/authid/detail.url?authorId=57201090782 | D8: Petrobras | E8: 0000-0001-6394-4672
A9: Tedeschi, Leonardo R. | B9: 57191364677 | C9: https://www.scopus.com/authid/detail.url?authorId=57191364677 | D9: Petrobras | E9: 0000-0002-0430-4437
A10: Maul, Alexandre Rodrigo M. | B10: 57189617898 | C10: https://www.scopus.com/authid/detail.url?authorId=57189617898 | D10: Petrobras
A11: de Souza, Jorge André Braz | B11: 57191664290 | C11: https://www.scopus.com/authid/detail.url?authorId=57191664290 | D11: Petrobras
A12: Campello, George Carneiro | B12: 23090256500 | C12: https://www.scopus.com/authid/detail.url?authorId=23090256500 | D12: Petrobras
A13: Pinho, Andrea De Rezende | B13: 16200428400 | C13: https://www.scopus.com/authid/detail.url?authorId=16200428400 | D13: Petrobras | E13: 0000-0003-1201-5296
A14: Lage, Antonio Carlos Vieira Martins | B14: 7005254211 | C14: https://www.scopus.com/authid/detail.url?authorId=7005254211 | D14: Petrobras
A15: Colombo, Danilo | B15: 57204642080 | C15: https://www.scopus.com/authid/detail.url?authorId=57204642080 | D15: Petrobras
A16: Viana, A. R. | B16: 7007140972 | C16: https://www.scopus.com/authid/detail.url?authorId=7007140972 | D16: Petrobras | E16: 0000-0001-8527-3080
A17: Teixeira, Leonardo Márcio | B17: 57197710300 | C17: https://www.scopus.com/authid/detail.url?authorId=57197710300 | D17: Petrobras
A18: Weschenfelder, Silvio Edegar | B18: 56094509400 | C18: https://www.scopus.com/authid/detail.url?authorId=56094509400 | D18: Universidade Federal do Rio de Janeiro
A19: Carvalho, Bruno Raphael Barbosa Melo De | B19: 56448255800 | C19: https://www.scopus.com/authid/detail.url?authorId=56448255800 | D19: Petrobras
A20: Waldmann, Alex Tadeu A.Almeida | B20: 6701636534 | C20: https://www.scopus.com/authid/detail.url?authorId=6701636534 | D20: Petrobras
A21: Solano, Rafael Familiar | B21: 56272705000 | C21: https://www.scopus.com/authid/detail.url?authorId=56272705000 | D21: Unknown affiliation
A22: Oliveira, Leonardo Costa De | B22: 57932702400 | C22: https://www.scopus.com/authid/detail.url?authorId=57932702400 | D22: Petrobras
A23: Szatmari, Peter | B23: 35231302900 | C23: https://www.scopus.com/authid/detail.url?authorId=35231302900 | D23: Petrobras
A24: de Oliveira, Diego Felipe Barbosa | B24: 56352999500 | C24: https://www.scopus.com/authid/detail.url?authorId=56352999500 | D24: Petrobras
A25: Johann, Paulo Roberto Schroeder | B25: 6701329330 | C25: https://www.scopus.com/authid/detail.url?authorId=6701329330 | D25: Petrobras
A26: Benjamin, Adilson C. | B26: 7102972518 | C26: https://www.scopus.com/authid/detail.url?authorId=7102972518 | D26: Petrobras
A27: Castro, Bruno Barbosa | B27: 57203411946 | C27: https://www.scopus.com/authid/detail.url?authorId=57203411946 | D27: Petrobras
A28: da Silva, Manoel Feliciano | B28: 57203414604 | C28: https://www.scopus.com/authid/detail.url?authorId=57203414604 | D28: Petrobras
... A32: Ferreira, Marcus Vinicius Duarte | B32: 7402787315 | C32: https://www.scopus.com/authid/detail.url?authorId=7402787315 | D32: Petrobras
A33: Aranha, P. E. | B33: 35145324200 | C33: https://www.scopus.com/authid/detail.url?authorId=35145324200 | D33: Petrobras | E33: 0000-0002-4225-1882
A34: Roman, Roger Savoldi | B34: 57202445572 | C34: https://www.scopus.com/authid/detail.url?authorId=57202445572 | D34: Petrobras
A35: Rodrigues, José Roberto Pereira | B35: 23135510600 | C35: https://www.scopus.com/authid/detail.url?authorId=23135510600 | D35: Petrobras
A36: Penna, Rodrigo Macedo | B36: 57164558000 | C36: https://www.scopus.com/authid/detail.url?authorId=57164558000 | D36: Petrobras
A37: Strugale, Michael | B37: 20735488300 | C37: https://www.scopus.com/authid/detail.url?authorId=20735488300 | D37: Petrobras | E37: 0000-0003-1106-7529
A38: Belo, Wellington Ceccopieri | B38: 11739629800 | C38: https://www.scopus.com/authid/detail.url?authorId=11739629800 | D38: Petrobras
A39: Ferreira, Marcos Donato Auler Da S. | B39: 7402784036 | C39: https://www.scopus.com/authid/detail.url?authorId=7402784036 | D39: Petrobras
A40: Pinto, Antônio Carlos Capeleiro | B40: 36155938800 | C40: https://www.scopus.com/authid/detail.url?authorId=36155938800 | D40: Petrobras
A41: Furtado, Claudio A. | B41: 55398602300 | C41: https://www.scopus.com/authid/detail.url?authorId=55398602300 | D41: Petrobras
A42: Cazarin, Caroline Lessio | B42: 56094347300 | C42: https://www.scopus.com/authid/detail.url?authorId=56094347300 | D42: Petrobras
A43: Paes, Marcelo Torres Piza | B43: 59830428600 | C43: https://www.scopus.com/authid/detail.url?authorId=59830428600 | D43: Petrobras
...
